Workbook

Sheet Stories
A1: ID | B1: Demo step | C1: Story | D1: Acceptance criteria | E1: Baseline SP | F1: Model | G1: Effort | H1: Multiplier | I1: Adjusted SP | J1: Status | K1: Accepted (Y/N) | L1: Actual runtime (min) | M1: Raw actual SP | N1: Normalised actual SP | O1: Variance
A2: S1 | B2: all | C2: Project scaffold in the fork: Node 22 TS package, npm scripts (`start`, `agent`, `reset`, `drop`, `compare`, `test`), `.env.example`, `.gitignore` for `.env` and `secrets/`, CI running unit tests, `appa describe --check` and `appa replay policy-tests/` | D2: `npm test` passes on a fresh clone; CI is green on the first PR; `git check-ignore .env secrets/x` matches both; no secret in the repo | E2: 2 | F2: Opus 5.5 | G2: medium | H2: =INDEX(Calibration!$D$5:$D$11,MATCH(F2&" "&G2,Calibration!$A$5:$A$11,0)) | I2: =E2*H2 | J2: Done | K2: Y | L2: =SUMIFS(Tasks!$P$2:$P$62,Tasks!$B$2:$B$62,A2) | M2: =IF(K2="Y",SUMIFS(Tasks!$T$2:$T$62,Tasks!$B$2:$B$62,A2),"") | N2: =IF(K2="Y",SUMIFS(Tasks!$U$2:$U$62,Tasks!$B$2:$B$62,A2),"") | O2: =IF(N2="","",N2-E2)
A3: S2 | B3: inputs, 1, 3 | C3: Write the 11 synthetic seed files listed in the demo script | D3: All 11 exist with the demo-script names; each starts with SPECIMEN; only 08 and 09 match `SPC-\d{4}-\d{4}`; 01 contains `Matter Ref: LM-2026-0417`; all names are fictional | E3: 1 | F3: Sonnet 5.5 | G3: medium | H3: =INDEX(Calibration!$D$5:$D$11,MATCH(F3&" "&G3,Calibration!$A$5:$A$11,0)) | I3: =E3*H3 | J3: Done | K3: Y | L3: =SUMIFS(Tasks!$P$2:$P$62,Tasks!$B$2:$B$62,A3) | M3: =IF(K3="Y",SUMIFS(Tasks!$T$2:$T$62,Tasks!$B$2:$B$62,A3),"") | N3: =IF(K3="Y",SUMIFS(Tasks!$U$2:$U$62,Tasks!$B$2:$B$62,A3),"") | O3: =IF(N3="","",N3-E3)
A4: S3 | B4: setup, 0, 1, 3 | C4: Drive client: list root, read, move, upload, trash, ensure subfolders. Auth is chosen by one `GDRIVE_AUTH` line (oauth, TBD, or service-account). Setup steps go in the README | D4: `npm run drive:check` lists the root and creates any missing subfolder; switching `GDRIVE_AUTH` needs no code change; the OAuth token is cached under `secrets/`; refuses to run if `GDRIVE_ROOT_FOLDER_ID` is unset | E4: 3 | F4: Opus 5.5 | G4: medium | H4: =INDEX(Calibration!$D$5:$D$11,MATCH(F4&" "&G4,Calibration!$A$5:$A$11,0)) | I4: =E4*H4 | J4: Done | K4: Y | L4: =SUMIFS(Tasks!$P$2:$P$62,Tasks!$B$2:$B$62,A4) | M4: =IF(K4="Y",SUMIFS(Tasks!$T$2:$T$62,Tasks!$B$2:$B$62,A4),"") | N4: =IF(K4="Y",SUMIFS(Tasks!$U$2:$U$62,Tasks!$B$2:$B$62,A4),"") | O4: =IF(N4="","",N4-E4)
A5: S4 | B5: 0 | C5: `npm run reset`: trash everything under the test folder, upload seed 01–10 to the root, archive `logs/` to `runs/<stamp>/`, clear the outbox, memory and poller state | D5: Step 0 "See" holds; running reset twice in a row gives the same state; it touches nothing outside `GDRIVE_ROOT_FOLDER_ID` (unit test with a fake Drive) | E5: 1 | F5: Opus 5.5 | G5: medium | H5: =INDEX(Calibration!$D$5:$D$11,MATCH(F5&" "&G5,Calibration!$A$5:$A$11,0)) | I5: =E5*H5 | J5: Done | K5: Y | L5: =SUMIFS(Tasks!$P$2:$P$62,Tasks!$B$2:$B$62,A5) | M5: =IF(K5="Y",SUMIFS(Tasks!$T$2:$T$62,Tasks!$B$2:$B$62,A5),"") | N5: =IF(K5="Y",SUMIFS(Tasks!$U$2:$U$62,Tasks!$B$2:$B$62,A5),"") | O5: =IF(N5="","",N5-E5)
A6: S5 | B6: 1, 3 | C6: Classifier: ID rule, then Jev `choice()` over {Legal, Accounting}, then the threshold; fixture replay or record-on-miss keyed by sha256(content) | D6: With the committed fixture and no API key, unit tests give the demo-script label and rule for all 11 files; a miss is logged `"source":"live"`; the threshold comes from `.env` | E6: 3 | F6: Opus 5.5 | G6: medium | H6: =INDEX(Calibration!$D$5:$D$11,MATCH(F6&" "&G6,Calibration!$A$5:$A$11,0)) | I6: =E6*H6 | J6: Done | K6: Y | L6: =SUMIFS(Tasks!$P$2:$P$62,Tasks!$B$2:$B$62,A6) | M6: =IF(K6="Y",SUMIFS(Tasks!$T$2:$T$62,Tasks!$B$2:$B$62,A6),"") | N6: =IF(K6="Y",SUMIFS(Tasks!$U$2:$U$62,Tasks!$B$2:$B$62,A6),"") | O6: =IF(N6="","",N6-E6)
A7: S6 | B7: 1, 3 | C7: Record the Jev fixture live for the 11 files and commit it (needs the TypeSafe key) | D7: File 10 records < 0.70; the other non-ID files record ≥ 0.70 with the expected label. If not, edit the seed text and re-record; never hand-edit the fixture | E7: 1 | F7: Opus 5.5 | G7: low | H7: =INDEX(Calibration!$D$5:$D$11,MATCH(F7&" "&G7,Calibration!$A$5:$A$11,0)) | I7: =E7*H7 | J7: Done | K7: Y | L7: =SUMIFS(Tasks!$P$2:$P$62,Tasks!$B$2:$B$62,A7) | M7: =IF(K7="Y",SUMIFS(Tasks!$T$2:$T$62,Tasks!$B$2:$B$62,A7),"") | N7: =IF(K7="Y",SUMIFS(Tasks!$U$2:$U$62,Tasks!$B$2:$B$62,A7),"") | O7: =IF(N7="","",N7-E7)
A8: S7 | B8: 1, 3 | C8: Poller: every 10 s, classify new root files, move them, log `classify` lines; ignore subfolders | D8: Step 1: 10 files moved within 30 s. Step 3: the new file moves within 30 s with no restart. A file already in a subfolder is never reclassified | E8: 2 | F8: Opus 5.5 | G8: medium | H8: =INDEX(Calibration!$D$5:$D$11,MATCH(F8&" "&G8,Calibration!$A$5:$A$11,0)) | I8: =E8*H8 | J8: Done | K8: Y | L8: =SUMIFS(Tasks!$P$2:$P$62,Tasks!$B$2:$B$62,A8) | M8: =IF(K8="Y",SUMIFS(Tasks!$T$2:$T$62,Tasks!$B$2:$B$62,A8),"") | N8: =IF(K8="Y",SUMIFS(Tasks!$U$2:$U$62,Tasks!$B$2:$B$62,A8),"") | O8: =IF(N8="","",N8-E8)
A9: S8 | B9: 1–4 | C9: Decision log writer (shared JSONL), plus `npm run compare` over two run folders, plus a check against `expected-decisions.json` built from this script | D9: Lines match the demo-script shapes; `compare` ignores timestamps and Drive IDs and sorts `classify` lines by file; it prints `identical`, or the first differing line and exits 1 | E9: 1 | F9: Sonnet 5.5 | G9: medium | H9: =INDEX(Calibration!$D$5:$D$11,MATCH(F9&" "&G9,Calibration!$A$5:$A$11,0)) | I9: =E9*H9 | J9: Done | K9: Y | L9: =SUMIFS(Tasks!$P$2:$P$62,Tasks!$B$2:$B$62,A9) | M9: =IF(K9="Y",SUMIFS(Tasks!$T$2:$T$62,Tasks!$B$2:$B$62,A9),"") | N9: =IF(K9="Y",SUMIFS(Tasks!$U$2:$U$62,Tasks!$B$2:$B$62,A9),"") | O9: =IF(N9="","",N9-E9)
A10: S9 | B10: 1, 2a–2d | C10: `appa.toml`: folder-labelled read tools, `send` with `contains = ["$to"]`, the `internal` list stub, memory save/load with scoped audiences, High Risk read denied. Plus `policy-tests/*.appa` | D10: `appa describe --check` passes; `appa replay` passes files for 2a (deny), 2b (deny), 2c across two sessions (deny), 2d (allow) and a High Risk read (deny) | E10: 3 | F10: Opus 5.5 | G10: high | H10: =INDEX(Calibration!$D$5:$D$11,MATCH(F10&" "&G10,Calibration!$A$5:$A$11,0)) | I10: =E10*H10 | J10: Done | K10: Y | L10: =SUMIFS(Tasks!$P$2:$P$62,Tasks!$B$2:$B$62,A10) | M10: =IF(K10="Y",SUMIFS(Tasks!$T$2:$T$62,Tasks!$B$2:$B$62,A10),"") | N10: =IF(K10="Y",SUMIFS(Tasks!$U$2:$U$62,Tasks!$B$2:$B$62,A10),"") | O10: =IF(N10="","",N10-E10)
A11: S10 | B11: 2a–2d | C11: Sidecar and TS hook client: `npm start` launches `appa runtime`; every tool call is checked before it runs; a deny returns the short reason, rewritten from runtime text plus the session's label source (file or memory) | D11: The exact 2a/2b/2c reason strings from the demo script are returned and logged; a denied call never runs its tool; unit tests use recorded runtime responses | E11: 3 | F11: Opus 5.5 | G11: high | H11: =INDEX(Calibration!$D$5:$D$11,MATCH(F11&" "&G11,Calibration!$A$5:$A$11,0)) | I11: =E11*H11 | J11: Done | K11: Y | L11: =SUMIFS(Tasks!$P$2:$P$62,Tasks!$B$2:$B$62,A11) | M11: =IF(K11="Y",SUMIFS(Tasks!$T$2:$T$62,Tasks!$B$2:$B$62,A11),"") | N11: =IF(K11="Y",SUMIFS(Tasks!$U$2:$U$62,Tasks!$B$2:$B$62,A11),"") | O11: =IF(N11="","",N11-E11)
A12: S11 | B12: 2 | C12: Tools: Drive read (returns content and folder label), mock `send` (appends to `logs/outbox.jsonl`), memory save/load (local JSON keyed by scope) | D12: Each tool works alone in unit tests; `send` writes exactly one line per allowed call and none per denied call | E12: 2 | F12: Opus 5.5 | G12: medium | H12: =INDEX(Calibration!$D$5:$D$11,MATCH(F12&" "&G12,Calibration!$A$5:$A$11,0)) | I12: =E12*H12 | J12: Done | K12: Y | L12: =SUMIFS(Tasks!$P$2:$P$62,Tasks!$B$2:$B$62,A12) | M12: =IF(K12="Y",SUMIFS(Tasks!$T$2:$T$62,Tasks!$B$2:$B$62,A12),"") | N12: =IF(K12="Y",SUMIFS(Tasks!$U$2:$U$62,Tasks!$B$2:$B$62,A12),"") | O12: =IF(N12="","",N12-E12)
A13: S12 | B13: 2 | C13: Scripted agent: takes the task text, runs agent-1 (read Legal, 2a, 2b, memory save), then agent-2 (memory load, send), then agent-1 2d; prints each result | D13: Step 2 "See" holds end to end against the live sidecar; outbox ends with exactly the 2d line; session IDs are fixed as `agent-1` and `agent-2` | E13: 2 | F13: Opus 5.5 | G13: medium | H13: =INDEX(Calibration!$D$5:$D$11,MATCH(F13&" "&G13,Calibration!$A$5:$A$11,0)) | I13: =E13*H13 | J13: Done | K13: Y | L13: =SUMIFS(Tasks!$P$2:$P$62,Tasks!$B$2:$B$62,A13) | M13: =IF(K13="Y",SUMIFS(Tasks!$T$2:$T$62,Tasks!$B$2:$B$62,A13),"") | N13: =IF(K13="Y",SUMIFS(Tasks!$U$2:$U$62,Tasks!$B$2:$B$62,A13),"") | O13: =IF(N13="","",N13-E13)
A14: Total | E14: =SUM(E2:E13) | I14: =SUM(I2:I13) | L14: =SUM(L2:L13) | M14: =SUM(M2:M13) | N14: =SUM(N2:N13) | O14: =IF(COUNTIF(K2:K13,"Y")=0,"",N14-SUMIFS(E2:E13,K2:K13,"Y"))
A16: Baseline SP is the product agent's story estimate (Phase 1). Variance = normalised actual SP − baseline SP; positive means the story took longer than estimated. Task-level estimates (Phase 2) are compared on the Summary tab.

Sheet Tasks
A1: ID | B1: Story ID | C1: Task | D1: Owner agent | E1: Wave | F1: Branch | G1: Files owned | H1: Dependencies | I1: Baseline SP | J1: Model | K1: Effort | L1: Multiplier | M1: Adjusted SP | N1: Start | O1: End | P1: Runtime (min) | Q1: Attempts | R1: PR link | S1: Accepted (Y/N) | T1: Raw actual SP | U1: Normalised actual SP | V1: Notes
A2: T1.1 | B2: S1 | C2: Node 22 TS package in `clearance/` with all npm scripts, stub CLIs, config loader, JSONL util, log schema and ignore rules. | D2: Rowan | E2: 1 | F2: feat/T1.1-node-scaffold | G2: `clearance/package.json`, `clearance/package-lock.json`, `clearance/tsconfig.json`, `clearance/vitest.config.ts`, `clearance/.env.example`, `clearance/README.md`, `clearance/src/config.ts`, `clearance/src/util/jsonl.ts`, `clearance/src/log/schema.ts`, `clearance/src/cli/{start,agent,reset,drop,compare,drive-check,record-fixture}.ts` (stubs), `clearance/test/config.test.ts`, `clearance/test/jsonl.test.ts`, `.gitignore`. | H2: none | I2: 2 | J2: Opus 5.5 | K2: medium | L2: =IF(J2="","",INDEX(Calibration!$D$5:$D$11,MATCH(J2&" "&K2,Calibration!$A$5:$A$11,0))) | M2: =IF(OR(I2="",L2=""),"",I2*L2) | N2: 46314.519 | O2: 46314.523 | P2: =IF(AND(ISNUMBER(N2),ISNUMBER(O2)),ROUND((O2-N2)*1440,1),"") | Q2: 1 | R2: https://github.com/soham956/OpenAPPA/pull/4 | S2: Y | T2: =IF(S2="Y",SUMIFS($P$2:$P$62,$A$2:$A$62,A2&"")/20,"") | U2: =IF(OR(T2="",L2=""),"",T2/L2) | V2: Accepted. Combined wave-1 check: vitest 30/30, typecheck ok, policy 8/8.
A3: T2.1 | B3: S2 | C3: Write the 11 synthetic SPECIMEN seed files. | D3: Mika | E3: 1 | F3: feat/T2.1-seed-files | G3: `clearance/seed/01-…10-*.txt`, `clearance/seed/new/11-vendor-invoice-0207.txt`, `clearance/test/seed.test.ts`. | H3: none | I3: 1 | J3: Sonnet 5.5 | K3: medium | L3: =IF(J3="","",INDEX(Calibration!$D$5:$D$11,MATCH(J3&" "&K3,Calibration!$A$5:$A$11,0))) | M3: =IF(OR(I3="",L3=""),"",I3*L3) | N3: 46314.524 | O3: 46314.525 | P3: =IF(AND(ISNUMBER(N3),ISNUMBER(O3)),ROUND((O3-N3)*1440,1),"") | Q3: 2 | R3: https://github.com/soham956/OpenAPPA/pull/2 | S3: Y | T3: =IF(S3="Y",SUMIFS($P$2:$P$62,$A$2:$A$62,A3&"")/20,"") | U3: =IF(OR(T3="",L3=""),"",T3/L3) | V3: Accepted after rework (attempt 2). Runtime includes the rejected attempt row.
A4: T9.1 | B4: S9 | C4: Policy and policy tests. First, spike array recipients (`@rcpt:addr/$to` with the node identity source) and switch to the documented fallback if it fails. | D4: Quinn | E4: 1 | F4: feat/T9.1-appa-policy | G4: `clearance/appa.toml`, `clearance/policy/rcpt-audience.mjs`, `clearance/policy/README.md`, `clearance/policy-tests/*.appa`. | H4: none (needs P1) | I4: 3 | J4: Opus 5.5 | K4: high | L4: =IF(J4="","",INDEX(Calibration!$D$5:$D$11,MATCH(J4&" "&K4,Calibration!$A$5:$A$11,0))) | M4: =IF(OR(I4="",L4=""),"",I4*L4) | N4: 46314.519 | O4: 46314.523 | P4: =IF(AND(ISNUMBER(N4),ISNUMBER(O4)),ROUND((O4-N4)*1440,1),"") | Q4: 1 | R4: https://github.com/soham956/OpenAPPA/pull/3 | S4: Y | T4: =IF(S4="Y",SUMIFS($P$2:$P$62,$A$2:$A$62,A4&"")/20,"") | U4: =IF(OR(T4="",L4=""),"",T4/L4) | V4: Accepted. Spike: array recipients via @rcpt:addr/$to work (no fallback). describe --check exit 0, replay 8/8 (orchestrator rerun).
A5: T1.2 | B5: S1 | C5: One CI workflow. Delete the upstream workflows, build `appa` with caching, and run the tests and policy checks. | D5: Rowan | E5: 2 | F5: feat/T1.2-ci | G5: `.github/workflows/clearance-ci.yml`. Deletes the 13 upstream `.github/workflows/*.yml` files and `.github/dependabot.yml`. | H5: T1.1, T9.1 | I5: 2 | J5: Opus 5.5 | K5: medium | L5: =IF(J5="","",INDEX(Calibration!$D$5:$D$11,MATCH(J5&" "&K5,Calibration!$A$5:$A$11,0))) | M5: =IF(OR(I5="",L5=""),"",I5*L5) | N5: 46314.552 | O5: 46314.556 | P5: =IF(AND(ISNUMBER(N5),ISNUMBER(O5)),ROUND((O5-N5)*1440,1),"") | Q5: 1 | R5: https://github.com/soham956/OpenAPPA/pull/11 | S5: Y | T5: =IF(S5="Y",SUMIFS($P$2:$P$62,$A$2:$A$62,A5&"")/20,"") | U5: =IF(OR(T5="",L5=""),"",T5/L5) | V5: Accepted: CI green cold (4m31s) and cached (19s, cache hit); check clearance-ci now required on main. Blocked 9.7 min waiting for Soham's workflow scope: wall-clock End-Start includes that; active time 8.1 min.
A6: T3.1 | B6: S3 | C6: `DriveClient` interface, the googleapis implementation and an in-memory fake. | D6: Sasha | E6: 2 | F6: feat/T3.1-drive-client | G6: `clearance/src/drive/{types,google,fake}.ts`, `clearance/test/drive-google.test.ts`, `clearance/test/drive-contract.test.ts`. | H6: T1.1 | I6: 2 | J6: Opus 5.5 | K6: medium | L6: =IF(J6="","",INDEX(Calibration!$D$5:$D$11,MATCH(J6&" "&K6,Calibration!$A$5:$A$11,0))) | M6: =IF(OR(I6="",L6=""),"",I6*L6) | N6: 46314.544 | O6: 46314.548 | P6: =IF(AND(ISNUMBER(N6),ISNUMBER(O6)),ROUND((O6-N6)*1440,1),"") | Q6: 1 | R6: https://github.com/soham956/OpenAPPA/pull/9 | S6: Y | T6: =IF(S6="Y",SUMIFS($P$2:$P$62,$A$2:$A$62,A6&"")/20,"") | U6: =IF(OR(T6="",L6=""),"",T6/L6) | V6: Accepted: in scope (5 files), contract suite runs on fake and Google stub, trash is soft (trashed=true), DriveScopeError outside the tree. Combined wave-2 check passed (128/128).
A7: T5.1 | B7: S5 | C7: ID rule, threshold decision and fixture store (replay, or record on a miss) keyed by sha256(content). | D7: Ellis | E7: 2 | F7: feat/T5.1-classifier-core | G7: `clearance/src/classifier/{types,specimen,decide,fixture-store}.ts`, `clearance/test/classifier.test.ts`, `clearance/test/fixtures/classifications.sample.json`. | H7: T1.1, T2.1 | I7: 2 | J7: Opus 5.5 | K7: medium | L7: =IF(J7="","",INDEX(Calibration!$D$5:$D$11,MATCH(J7&" "&K7,Calibration!$A$5:$A$11,0))) | M7: =IF(OR(I7="",L7=""),"",I7*L7) | N7: 46314.572 | O7: 46314.574 | P7: =IF(AND(ISNUMBER(N7),ISNUMBER(O7)),ROUND((O7-N7)*1440,1),"") | Q7: 2 | R7: https://github.com/soham956/OpenAPPA/pull/8 + #23 (rework) | S7: Y | T7: =IF(S7="Y",SUMIFS($P$2:$P$62,$A$2:$A$62,A7&"")/20,"") | U7: =IF(OR(T7="",L7=""),"",T7/L7) | V7: Accepted after rework (PR #23): fixture built from seed files at test time, no writes to committed files. Original PR #8 work counted as the rejected attempt row.
A8: T8.1 | B8: S8 | C8: Decision log writer and reader on top of `schema.ts`. | D8: Mika | E8: 2 | F8: feat/T8.1-decision-log | G8: `clearance/src/log/decision-log.ts`, `clearance/test/decision-log.test.ts`. | H8: T1.1 | I8: 1 | J8: Sonnet 5.5 | K8: medium | L8: =IF(J8="","",INDEX(Calibration!$D$5:$D$11,MATCH(J8&" "&K8,Calibration!$A$5:$A$11,0))) | M8: =IF(OR(I8="",L8=""),"",I8*L8) | N8: 46314.544 | O8: 46314.545 | P8: =IF(AND(ISNUMBER(N8),ISNUMBER(O8)),ROUND((O8-N8)*1440,1),"") | Q8: 1 | R8: https://github.com/soham956/OpenAPPA/pull/6 | S8: Y | T8: =IF(S8="Y",SUMIFS($P$2:$P$62,$A$2:$A$62,A8&"")/20,"") | U8: =IF(OR(T8="",L8=""),"",T8/L8) | V8: Accepted: in scope (2 files), exact-string tests of demo-script lines; combined wave-2 check passed (128/128).
A9: T10.1 | B9: S10 | C9: Sidecar launcher, typed `/hook` client and remedy executor over MCP. | D9: Quinn | E9: 2 | F9: feat/T10.1-sidecar-wire | G9: `clearance/src/sidecar/{runtime,wire,remedy}.ts`, `clearance/test/sidecar-wire.test.ts`, `clearance/test/sidecar-live.test.ts`, `clearance/test/fixtures/runtime/*.json`. | H9: T1.1, T9.1 | I9: 3 | J9: Opus 5.5 | K9: high | L9: =IF(J9="","",INDEX(Calibration!$D$5:$D$11,MATCH(J9&" "&K9,Calibration!$A$5:$A$11,0))) | M9: =IF(OR(I9="",L9=""),"",I9*L9) | N9: 46314.544 | O9: 46314.548 | P9: =IF(AND(ISNUMBER(N9),ISNUMBER(O9)),ROUND((O9-N9)*1440,1),"") | Q9: 1 | R9: https://github.com/soham956/OpenAPPA/pull/10 | S9: Y | T9: =IF(S9="Y",SUMIFS($P$2:$P$62,$A$2:$A$62,A9&"")/20,"") | U9: =IF(OR(T9="",L9=""),"",T9/L9) | V9: Accepted: live remedy flow against real appa; combined wave-2 check 128/128 incl. live, typecheck ok, policy 8/8. Live feedback wording differs from replay (T10.2 must use recorded fixtures).
A10: T11.1 | B10: S11 | C10: Mock `send` (outbox) and the memory save/load tools. | D10: Remy | E10: 2 | F10: feat/T11.1-send-memory-tools | G10: `clearance/src/tools/{send,memory}.ts`, `clearance/test/tools-send.test.ts`, `clearance/test/tools-memory.test.ts`. | H10: T1.1 | I10: 1 | J10: Sonnet 5.5 | K10: medium | L10: =IF(J10="","",INDEX(Calibration!$D$5:$D$11,MATCH(J10&" "&K10,Calibration!$A$5:$A$11,0))) | M10: =IF(OR(I10="",L10=""),"",I10*L10) | N10: 46314.544 | O10: 46314.546 | P10: =IF(AND(ISNUMBER(N10),ISNUMBER(O10)),ROUND((O10-N10)*1440,1),"") | Q10: 1 | R10: https://github.com/soham956/OpenAPPA/pull/7 | S10: Y | T10: =IF(S10="Y",SUMIFS($P$2:$P$62,$A$2:$A$62,A10&"")/20,"") | U10: =IF(OR(T10="",L10=""),"",T10/L10) | V10: Accepted: in scope (4 files), no APPA calls, outbox written via schema orderKeys; combined wave-2 check passed (128/128). PR body end time 13:06:00Z is slightly off; real end used.
A11: T3.2 | B11: S3 | C11: `GDRIVE_AUTH` switch (oauth or service-account), OAuth loopback consent with a token cache, factory, `npm run drive:check`, setup doc. | D11: Sasha | E11: 3 | F11: feat/T3.2-drive-auth | G11: `clearance/src/drive/{auth,factory}.ts`, `clearance/src/cli/drive-check.ts`, `clearance/docs/drive-setup.md`, `clearance/test/drive-auth.test.ts`. | H11: T1.1, T3.1 | I11: 2 | J11: Opus 5.5 | K11: medium | L11: =IF(J11="","",INDEX(Calibration!$D$5:$D$11,MATCH(J11&" "&K11,Calibration!$A$5:$A$11,0))) | M11: =IF(OR(I11="",L11=""),"",I11*L11) | N11: 46314.562 | O11: 46314.565 | P11: =IF(AND(ISNUMBER(N11),ISNUMBER(O11)),ROUND((O11-N11)*1440,1),"") | Q11: 1 | R11: https://github.com/soham956/OpenAPPA/pull/19 | S11: Y | T11: =IF(S11="Y",SUMIFS($P$2:$P$62,$A$2:$A$62,A11&"")/20,"") | U11: =IF(OR(T11="",L11=""),"",T11/L11) | V11: Accepted: CI green, 16 tests with stubs, PKCE loopback consent (127.0.0.1), token mode 600, no live run. Combined wave-3 check 220/220.
A12: T4.1 | B12: S4 | C12: `npm run reset` and `npm run drop`. | D12: Rowan | E12: 3 | F12: feat/T4.1-reset-drop | G12: `clearance/src/reset/reset.ts`, `clearance/src/cli/{reset,drop}.ts`, `clearance/test/reset.test.ts`. | H12: T1.1, T3.1 | I12: 1 | J12: Opus 5.5 | K12: medium | L12: =IF(J12="","",INDEX(Calibration!$D$5:$D$11,MATCH(J12&" "&K12,Calibration!$A$5:$A$11,0))) | M12: =IF(OR(I12="",L12=""),"",I12*L12) | N12: 46314.562 | O12: 46314.564 | P12: =IF(AND(ISNUMBER(N12),ISNUMBER(O12)),ROUND((O12-N12)*1440,1),"") | Q12: 1 | R12: https://github.com/soham956/OpenAPPA/pull/17 | S12: Y | T12: =IF(S12="Y",SUMIFS($P$2:$P$62,$A$2:$A$62,A12&"")/20,"") | U12: =IF(OR(T12="",L12=""),"",T12/L12) | V12: Accepted: in scope, CI green, 13 tests on fake incl. outsideTreeIds()=[] and sidecar refusal. Real Drive factory not yet wired (TODO(T3.2) seam) - wiring scheduled for wave 4. Combined wave-3 check 220/220.
A13: T5.2 | B13: S5 | C13: TypeSafe `choice()` adapter and the `npm run fixture:record` CLI. | D13: Ellis | E13: 3 | F13: feat/T5.2-jev-adapter | G13: `clearance/src/classifier/jev.ts`, `clearance/src/cli/record-fixture.ts`, `clearance/test/jev.test.ts`. | H13: T5.1 | I13: 1 | J13: Opus 5.5 | K13: medium | L13: =IF(J13="","",INDEX(Calibration!$D$5:$D$11,MATCH(J13&" "&K13,Calibration!$A$5:$A$11,0))) | M13: =IF(OR(I13="",L13=""),"",I13*L13) | N13: 46314.562 | O13: 46314.565 | P13: =IF(AND(ISNUMBER(N13),ISNUMBER(O13)),ROUND((O13-N13)*1440,1),"") | Q13: 1 | R13: https://github.com/soham956/OpenAPPA/pull/18 | S13: Y | T13: =IF(S13="Y",SUMIFS($P$2:$P$62,$A$2:$A$62,A13&"")/20,"") | U13: =IF(OR(T13="",L13=""),"",T13/L13) | V13: Accepted: CI green, each commit builds, SDK mocked, content-only. Orchestrator ruling: fixture holds 9 entries (08/09 never reach Jev - ID rule first); demo-script wording to be corrected.
... A22: T12.2 | B22: S12 | C22: CI end-to-end test of step 2 with the real `appa` sidecar and a fake Drive. | D22: Rowan | E22: 5 | F22: feat/T12.2-e2e-step2 | G22: `clearance/test/e2e/step2.test.ts`, `clearance/test/e2e/helpers.ts`. | H22: T12.1, T8.2 | I22: 2 | J22: Opus 5.5 | K22: medium | L22: =IF(J22="","",INDEX(Calibration!$D$5:$D$11,MATCH(J22&" "&K22,Calibration!$A$5:$A$11,0))) | M22: =IF(OR(I22="",L22=""),"",I22*L22) | N22: 46314.579 | O22: 46314.581 | P22: =IF(AND(ISNUMBER(N22),ISNUMBER(O22)),ROUND((O22-N22)*1440,1),"") | Q22: 1 | R22: https://github.com/soham956/OpenAPPA/pull/29 | S22: Y | T22: =IF(S22="Y",SUMIFS($P$2:$P$62,$A$2:$A$62,A22&"")/20,"") | U22: =IF(OR(T22="",L22=""),"",T22/L22) | V22: Accepted: e2e step 2 against real appa + fake Drive, conforms to expected (11 enforce + 1 outbox), second run identical, ran in CI (not skipped).
A23: T2.1 | B23: S2 | D23: Mika | E23: 1 | J23: Sonnet 5.5 | K23: medium | L23: =IF(J23="","",INDEX(Calibration!$D$5:$D$11,MATCH(J23&" "&K23,Calibration!$A$5:$A$11,0))) | M23: =IF(OR(I23="",L23=""),"",I23*L23) | N23: 46314.519 | O23: 46314.521 | P23: =IF(AND(ISNUMBER(N23),ISNUMBER(O23)),ROUND((O23-N23)*1440,1),"") | S23: N | T23: =IF(S23="Y",SUMIFS($P$2:$P$62,$A$2:$A$62,A23&"")/20,"") | U23: =IF(OR(T23="",L23=""),"",T23/L23) | V23: Rejected attempt 1: tsc TS2345 at seed.test.ts:50 (only visible once T1.1's TypeScript was applied).
A24: T5.1 | B24: S5 | D24: Ellis | E24: 2 | J24: Opus 5.5 | K24: medium | L24: =IF(J24="","",INDEX(Calibration!$D$5:$D$11,MATCH(J24&" "&K24,Calibration!$A$5:$A$11,0))) | M24: =IF(OR(I24="",L24=""),"",I24*L24) | N24: 46314.544 | O24: 46314.546 | P24: =IF(AND(ISNUMBER(N24),ISNUMBER(O24)),ROUND((O24-N24)*1440,1),"") | S24: N | T24: =IF(S24="Y",SUMIFS($P$2:$P$62,$A$2:$A$62,A24&"")/20,"") | U24: =IF(OR(T24="",L24=""),"",T24/L24) | V24: Original attempt: later found defective (sample fixture keyed to seed-10 hash; tests wrote into committed fixture) - superseded by rework.
A25: T1.2 | B25: S1 | D25: Rowan | E25: 2 | J25: Opus 5.5 | K25: medium | L25: =IF(J25="","",INDEX(Calibration!$D$5:$D$11,MATCH(J25&" "&K25,Calibration!$A$5:$A$11,0))) | M25: =IF(OR(I25="",L25=""),"",I25*L25) | N25: 46314.544 | O25: 46314.545 | P25: =IF(AND(ISNUMBER(N25),ISNUMBER(O25)),ROUND((O25-N25)*1440,1),"") | T25: =IF(S25="Y",SUMIFS($P$2:$P$62,$A$2:$A$62,A25&"")/20,"") | U25: =IF(OR(T25="",L25=""),"",T25/L25) | V25: Earlier work segment of the accepted attempt (paused while blocked).
A26: T8.2 | B26: S8 | D26: Mika | E26: 3 | J26: Sonnet 5.5 | K26: medium | L26: =IF(J26="","",INDEX(Calibration!$D$5:$D$11,MATCH(J26&" "&K26,Calibration!$A$5:$A$11,0))) | M26: =IF(OR(I26="",L26=""),"",I26*L26) | N26: 46314.574 | O26: 46314.575 | P26: =IF(AND(ISNUMBER(N26),ISNUMBER(O26)),ROUND((O26-N26)*1440,1),"") | R26: https://github.com/soham956/OpenAPPA/pull/26 | T26: =IF(S26="Y",SUMIFS($P$2:$P$62,$A$2:$A$62,A26&"")/20,"") | U26: =IF(OR(T26="",L26=""),"",T26/L26) | V26: Follow-up (orchestrator request, not rework): expected list line for guarded drive_list (PR #26, merges after #24)
A27: T4.1 | B27: S4 | D27: Rowan | E27: 3 | J27: Opus 5.5 | K27: medium | L27: =IF(J27="","",INDEX(Calibration!$D$5:$D$11,MATCH(J27&" "&K27,Calibration!$A$5:$A$11,0))) | M27: =IF(OR(I27="",L27=""),"",I27*L27) | N27: 46314.57 | O27: 46314.572 | P27: =IF(AND(ISNUMBER(N27),ISNUMBER(O27)),ROUND((O27-N27)*1440,1),"") | R27: https://github.com/soham956/OpenAPPA/pull/21 | T27: =IF(S27="Y",SUMIFS($P$2:$P$62,$A$2:$A$62,A27&"")/20,"") | U27: =IF(OR(T27="",L27=""),"",T27/L27) | V27: Follow-up (orchestrator request, not rework): wire Drive factory into reset/drop (PR #21)
A28: T10.2 | B28: S10 | D28: Quinn | E28: 3 | J28: Opus 5.5 | K28: high | L28: =IF(J28="","",INDEX(Calibration!$D$5:$D$11,MATCH(J28&" "&K28,Calibration!$A$5:$A$11,0))) | M28: =IF(OR(I28="",L28=""),"",I28*L28) | N28: 46314.577 | O28: 46314.578 | P28: =IF(AND(ISNUMBER(N28),ISNUMBER(O28)),ROUND((O28-N28)*1440,1),"") | R28: https://github.com/soham956/OpenAPPA/pull/27 | T28: =IF(S28="Y",SUMIFS($P$2:$P$62,$A$2:$A$62,A28&"")/20,"") | U28: =IF(OR(T28="",L28=""),"",T28/L28) | V28: Follow-up (orchestrator request, not rework): guard logs caller's step for drive_list (PR #27)
A29: T6.1 | B29: S6 | D29: Noor | E29: 4 | J29: Opus 5.5 | K29: low | L29: =IF(J29="","",INDEX(Calibration!$D$5:$D$11,MATCH(J29&" "&K29,Calibration!$A$5:$A$11,0))) | M29: =IF(OR(I29="",L29=""),"",I29*L29) | N29: 46314.57 | O29: 46314.572 | P29: =IF(AND(ISNUMBER(N29),ISNUMBER(O29)),ROUND((O29-N29)*1440,1),"") | T29: =IF(S29="Y",SUMIFS($P$2:$P$62,$A$2:$A$62,A29&"")/20,"") | U29: =IF(OR(T29="",L29=""),"",T29/L29) | V29: Earlier work segment of the accepted attempt (paused while blocked).
A30: T12.1 | B30: S12 | D30: Rowan | E30: 4 | J30: Opus 5.5 | K30: medium | L30: =IF(J30="","",INDEX(Calibration!$D$5:$D$11,MATCH(J30&" "&K30,Calibration!$A$5:$A$11,0))) | M30: =IF(OR(I30="",L30=""),"",I30*L30) | N30: 46314.572 | O30: 46314.574 | P30: =IF(AND(ISNUMBER(N30),ISNUMBER(O30)),ROUND((O30-N30)*1440,1),"") | S30: N | T30: =IF(S30="Y",SUMIFS($P$2:$P$62,$A$2:$A$62,A30&"")/20,"") | U30: =IF(OR(T30="",L30=""),"",T30/L30) | V30: Rejected attempt 1: agent discovered Legal files via unguarded DriveClient.list to fit expected file; orchestrator requires guarded drive_list under new 'list' step.
L31: =IF(J31="","",INDEX(Calibration!$D$5:$D$11,MATCH(J31&" "&K31,Calibration!$A$5:$A$11,0))) | M31: =IF(OR(I31="",L31=""),"",I31*L31) | P31: =IF(AND(ISNUMBER(N31),ISNUMBER(O31)),ROUND((O31-N31)*1440,1),"") | T31: =IF(S31="Y",SUMIFS($P$2:$P$62,$A$2:$A$62,A31&"")/20,"") | U31: =IF(OR(T31="",L31=""),"",T31/L31)
L32: =IF(J32="","",INDEX(Calibration!$D$5:$D$11,MATCH(J32&" "&K32,Calibration!$A$5:$A$11,0))) | M32: =IF(OR(I32="",L32=""),"",I32*L32) | P32: =IF(AND(ISNUMBER(N32),ISNUMBER(O32)),ROUND((O32-N32)*1440,1),"") | T32: =IF(S32="Y",SUMIFS($P$2:$P$62,$A$2:$A$62,A32&"")/20,"") | U32: =IF(OR(T32="",L32=""),"",T32/L32)
L33: =IF(J33="","",INDEX(Calibration!$D$5:$D$11,MATCH(J33&" "&K33,Calibration!$A$5:$A$11,0))) | M33: =IF(OR(I33="",L33=""),"",I33*L33) | P33: =IF(AND(ISNUMBER(N33),ISNUMBER(O33)),ROUND((O33-N33)*1440,1),"") | T33: =IF(S33="Y",SUMIFS($P$2:$P$62,$A$2:$A$62,A33&"")/20,"") | U33: =IF(OR(T33="",L33=""),"",T33/L33)
L34: =IF(J34="","",INDEX(Calibration!$D$5:$D$11,MATCH(J34&" "&K34,Calibration!$A$5:$A$11,0))) | M34: =IF(OR(I34="",L34=""),"",I34*L34) | P34: =IF(AND(ISNUMBER(N34),ISNUMBER(O34)),ROUND((O34-N34)*1440,1),"") | T34: =IF(S34="Y",SUMIFS($P$2:$P$62,$A$2:$A$62,A34&"")/20,"") | U34: =IF(OR(T34="",L34=""),"",T34/L34)
L35: =IF(J35="","",INDEX(Calibration!$D$5:$D$11,MATCH(J35&" "&K35,Calibration!$A$5:$A$11,0))) | M35: =IF(OR(I35="",L35=""),"",I35*L35) | P35: =IF(AND(ISNUMBER(N35),ISNUMBER(O35)),ROUND((O35-N35)*1440,1),"") | T35: =IF(S35="Y",SUMIFS($P$2:$P$62,$A$2:$A$62,A35&"")/20,"") | U35: =IF(OR(T35="",L35=""),"",T35/L35)
L36: =IF(J36="","",INDEX(Calibration!$D$5:$D$11,MATCH(J36&" "&K36,Calibration!$A$5:$A$11,0))) | M36: =IF(OR(I36="",L36=""),"",I36*L36) | P36: =IF(AND(ISNUMBER(N36),ISNUMBER(O36)),ROUND((O36-N36)*1440,1),"") | T36: =IF(S36="Y",SUMIFS($P$2:$P$62,$A$2:$A$62,A36&"")/20,"") | U36: =IF(OR(T36="",L36=""),"",T36/L36)
L37: =IF(J37="","",INDEX(Calibration!$D$5:$D$11,MATCH(J37&" "&K37,Calibration!$A$5:$A$11,0))) | M37: =IF(OR(I37="",L37=""),"",I37*L37) | P37: =IF(AND(ISNUMBER(N37),ISNUMBER(O37)),ROUND((O37-N37)*1440,1),"") | T37: =IF(S37="Y",SUMIFS($P$2:$P$62,$A$2:$A$62,A37&"")/20,"") | U37: =IF(OR(T37="",L37=""),"",T37/L37)
L38: =IF(J38="","",INDEX(Calibration!$D$5:$D$11,MATCH(J38&" "&K38,Calibration!$A$5:$A$11,0))) | M38: =IF(OR(I38="",L38=""),"",I38*L38) | P38: =IF(AND(ISNUMBER(N38),ISNUMBER(O38)),ROUND((O38-N38)*1440,1),"") | T38: =IF(S38="Y",SUMIFS($P$2:$P$62,$A$2:$A$62,A38&"")/20,"") | U38: =IF(OR(T38="",L38=""),"",T38/L38)
L39: =IF(J39="","",INDEX(Calibration!$D$5:$D$11,MATCH(J39&" "&K39,Calibration!$A$5:$A$11,0))) | M39: =IF(OR(I39="",L39=""),"",I39*L39) | P39: =IF(AND(ISNUMBER(N39),ISNUMBER(O39)),ROUND((O39-N39)*1440,1),"") | T39: =IF(S39="Y",SUMIFS($P$2:$P$62,$A$2:$A$62,A39&"")/20,"") | U39: =IF(OR(T39="",L39=""),"",T39/L39)
L40: =IF(J40="","",INDEX(Calibration!$D$5:$D$11,MATCH(J40&" "&K40,Calibration!$A$5:$A$11,0))) | M40: =IF(OR(I40="",L40=""),"",I40*L40) | P40: =IF(AND(ISNUMBER(N40),ISNUMBER(O40)),ROUND((O40-N40)*1440,1),"") | T40: =IF(S40="Y",SUMIFS($P$2:$P$62,$A$2:$A$62,A40&"")/20,"") | U40: =IF(OR(T40="",L40=""),"",T40/L40)
L41: =IF(J41="","",INDEX(Calibration!$D$5:$D$11,MATCH(J41&" "&K41,Calibration!$A$5:$A$11,0))) | M41: =IF(OR(I41="",L41=""),"",I41*L41) | P41: =IF(AND(ISNUMBER(N41),ISNUMBER(O41)),ROUND((O41-N41)*1440,1),"") | T41: =IF(S41="Y",SUMIFS($P$2:$P$62,$A$2:$A$62,A41&"")/20,"") | U41: =IF(OR(T41="",L41=""),"",T41/L41)
L42: =IF(J42="","",INDEX(Calibration!$D$5:$D$11,MATCH(J42&" "&K42,Calibration!$A$5:$A$11,0))) | M42: =IF(OR(I42="",L42=""),"",I42*L42) | P42: =IF(AND(ISNUMBER(N42),ISNUMBER(O42)),ROUND((O42-N42)*1440,1),"") | T42: =IF(S42="Y",SUMIFS($P$2:$P$62,$A$2:$A$62,A42&"")/20,"") | U42: =IF(OR(T42="",L42=""),"",T42/L42)
... L62: =IF(J62="","",INDEX(Calibration!$D$5:$D$11,MATCH(J62&" "&K62,Calibration!$A$5:$A$11,0))) | M62: =IF(OR(I62="",L62=""),"",I62*L62) | P62: =IF(AND(ISNUMBER(N62),ISNUMBER(O62)),ROUND((O62-N62)*1440,1),"") | T62: =IF(S62="Y",SUMIFS($P$2:$P$62,$A$2:$A$62,A62&"")/20,"") | U62: =IF(OR(T62="",L62=""),"",T62/L62)

Sheet Agents
A1: Agent | B1: Model | C1: Effort | D1: Multiplier | E1: Lane | F1: Tasks assigned | G1: Tasks accepted | H1: Rejected attempts | I1: Baseline SP | J1: Adjusted SP | K1: Runtime (min) | L1: Raw actual SP | M1: Normalised actual SP | N1: Actual ÷ estimate (raw ÷ adjusted, accepted)
A2: Quinn | B2: Opus 5.5 | C2: high | D2: =INDEX(Calibration!$D$5:$D$11,MATCH(B2&" "&C2,Calibration!$A$5:$A$11,0)) | E2: Policy and sidecar | F2: =COUNTIFS(Tasks!$D$2:$D$62,$A2,Tasks!$I$2:$I$62,">0") | G2: =COUNTIFS(Tasks!$D$2:$D$62,$A2,Tasks!$S$2:$S$62,"Y") | H2: =COUNTIFS(Tasks!$D$2:$D$62,$A2,Tasks!$S$2:$S$62,"N")-COUNTIFS(Tasks!$D$2:$D$62,$A2,Tasks!$S$2:$S$62,"N",Tasks!$I$2:$I$62,">0") | I2: =SUMIFS(Tasks!$I$2:$I$62,Tasks!$D$2:$D$62,$A2) | J2: =SUMIFS(Tasks!$M$2:$M$62,Tasks!$D$2:$D$62,$A2) | K2: =SUMIFS(Tasks!$P$2:$P$62,Tasks!$D$2:$D$62,$A2) | L2: =SUMIFS(Tasks!$T$2:$T$62,Tasks!$D$2:$D$62,$A2) | M2: =SUMIFS(Tasks!$U$2:$U$62,Tasks!$D$2:$D$62,$A2) | N2: =IF(SUMIFS(Tasks!$M$2:$M$62,Tasks!$D$2:$D$62,$A2,Tasks!$S$2:$S$62,"Y")=0,"",L2/SUMIFS(Tasks!$M$2:$M$62,Tasks!$D$2:$D$62,$A2,Tasks!$S$2:$S$62,"Y"))
A3: Rowan | B3: Opus 5.5 | C3: medium | D3: =INDEX(Calibration!$D$5:$D$11,MATCH(B3&" "&C3,Calibration!$A$5:$A$11,0)) | E3: Platform: scaffold, CI, reset, agent, e2e | F3: =COUNTIFS(Tasks!$D$2:$D$62,$A3,Tasks!$I$2:$I$62,">0") | G3: =COUNTIFS(Tasks!$D$2:$D$62,$A3,Tasks!$S$2:$S$62,"Y") | H3: =COUNTIFS(Tasks!$D$2:$D$62,$A3,Tasks!$S$2:$S$62,"N")-COUNTIFS(Tasks!$D$2:$D$62,$A3,Tasks!$S$2:$S$62,"N",Tasks!$I$2:$I$62,">0") | I3: =SUMIFS(Tasks!$I$2:$I$62,Tasks!$D$2:$D$62,$A3) | J3: =SUMIFS(Tasks!$M$2:$M$62,Tasks!$D$2:$D$62,$A3) | K3: =SUMIFS(Tasks!$P$2:$P$62,Tasks!$D$2:$D$62,$A3) | L3: =SUMIFS(Tasks!$T$2:$T$62,Tasks!$D$2:$D$62,$A3) | M3: =SUMIFS(Tasks!$U$2:$U$62,Tasks!$D$2:$D$62,$A3) | N3: =IF(SUMIFS(Tasks!$M$2:$M$62,Tasks!$D$2:$D$62,$A3,Tasks!$S$2:$S$62,"Y")=0,"",L3/SUMIFS(Tasks!$M$2:$M$62,Tasks!$D$2:$D$62,$A3,Tasks!$S$2:$S$62,"Y"))
A4: Sasha | B4: Opus 5.5 | C4: medium | D4: =INDEX(Calibration!$D$5:$D$11,MATCH(B4&" "&C4,Calibration!$A$5:$A$11,0)) | E4: Drive | F4: =COUNTIFS(Tasks!$D$2:$D$62,$A4,Tasks!$I$2:$I$62,">0") | G4: =COUNTIFS(Tasks!$D$2:$D$62,$A4,Tasks!$S$2:$S$62,"Y") | H4: =COUNTIFS(Tasks!$D$2:$D$62,$A4,Tasks!$S$2:$S$62,"N")-COUNTIFS(Tasks!$D$2:$D$62,$A4,Tasks!$S$2:$S$62,"N",Tasks!$I$2:$I$62,">0") | I4: =SUMIFS(Tasks!$I$2:$I$62,Tasks!$D$2:$D$62,$A4) | J4: =SUMIFS(Tasks!$M$2:$M$62,Tasks!$D$2:$D$62,$A4) | K4: =SUMIFS(Tasks!$P$2:$P$62,Tasks!$D$2:$D$62,$A4) | L4: =SUMIFS(Tasks!$T$2:$T$62,Tasks!$D$2:$D$62,$A4) | M4: =SUMIFS(Tasks!$U$2:$U$62,Tasks!$D$2:$D$62,$A4) | N4: =IF(SUMIFS(Tasks!$M$2:$M$62,Tasks!$D$2:$D$62,$A4,Tasks!$S$2:$S$62,"Y")=0,"",L4/SUMIFS(Tasks!$M$2:$M$62,Tasks!$D$2:$D$62,$A4,Tasks!$S$2:$S$62,"Y"))
A5: Ellis | B5: Opus 5.5 | C5: medium | D5: =INDEX(Calibration!$D$5:$D$11,MATCH(B5&" "&C5,Calibration!$A$5:$A$11,0)) | E5: Classifier | F5: =COUNTIFS(Tasks!$D$2:$D$62,$A5,Tasks!$I$2:$I$62,">0") | G5: =COUNTIFS(Tasks!$D$2:$D$62,$A5,Tasks!$S$2:$S$62,"Y") | H5: =COUNTIFS(Tasks!$D$2:$D$62,$A5,Tasks!$S$2:$S$62,"N")-COUNTIFS(Tasks!$D$2:$D$62,$A5,Tasks!$S$2:$S$62,"N",Tasks!$I$2:$I$62,">0") | I5: =SUMIFS(Tasks!$I$2:$I$62,Tasks!$D$2:$D$62,$A5) | J5: =SUMIFS(Tasks!$M$2:$M$62,Tasks!$D$2:$D$62,$A5) | K5: =SUMIFS(Tasks!$P$2:$P$62,Tasks!$D$2:$D$62,$A5) | L5: =SUMIFS(Tasks!$T$2:$T$62,Tasks!$D$2:$D$62,$A5) | M5: =SUMIFS(Tasks!$U$2:$U$62,Tasks!$D$2:$D$62,$A5) | N5: =IF(SUMIFS(Tasks!$M$2:$M$62,Tasks!$D$2:$D$62,$A5,Tasks!$S$2:$S$62,"Y")=0,"",L5/SUMIFS(Tasks!$M$2:$M$62,Tasks!$D$2:$D$62,$A5,Tasks!$S$2:$S$62,"Y"))
A6: Jules | B6: Opus 5.5 | C6: medium | D6: =INDEX(Calibration!$D$5:$D$11,MATCH(B6&" "&C6,Calibration!$A$5:$A$11,0)) | E6: Poller | F6: =COUNTIFS(Tasks!$D$2:$D$62,$A6,Tasks!$I$2:$I$62,">0") | G6: =COUNTIFS(Tasks!$D$2:$D$62,$A6,Tasks!$S$2:$S$62,"Y") | H6: =COUNTIFS(Tasks!$D$2:$D$62,$A6,Tasks!$S$2:$S$62,"N")-COUNTIFS(Tasks!$D$2:$D$62,$A6,Tasks!$S$2:$S$62,"N",Tasks!$I$2:$I$62,">0") | I6: =SUMIFS(Tasks!$I$2:$I$62,Tasks!$D$2:$D$62,$A6) | J6: =SUMIFS(Tasks!$M$2:$M$62,Tasks!$D$2:$D$62,$A6) | K6: =SUMIFS(Tasks!$P$2:$P$62,Tasks!$D$2:$D$62,$A6) | L6: =SUMIFS(Tasks!$T$2:$T$62,Tasks!$D$2:$D$62,$A6) | M6: =SUMIFS(Tasks!$U$2:$U$62,Tasks!$D$2:$D$62,$A6) | N6: =IF(SUMIFS(Tasks!$M$2:$M$62,Tasks!$D$2:$D$62,$A6,Tasks!$S$2:$S$62,"Y")=0,"",L6/SUMIFS(Tasks!$M$2:$M$62,Tasks!$D$2:$D$62,$A6,Tasks!$S$2:$S$62,"Y"))
A7: Mika | B7: Sonnet 5.5 | C7: medium | D7: =INDEX(Calibration!$D$5:$D$11,MATCH(B7&" "&C7,Calibration!$A$5:$A$11,0)) | E7: Seed data and decision log | F7: =COUNTIFS(Tasks!$D$2:$D$62,$A7,Tasks!$I$2:$I$62,">0") | G7: =COUNTIFS(Tasks!$D$2:$D$62,$A7,Tasks!$S$2:$S$62,"Y") | H7: =COUNTIFS(Tasks!$D$2:$D$62,$A7,Tasks!$S$2:$S$62,"N")-COUNTIFS(Tasks!$D$2:$D$62,$A7,Tasks!$S$2:$S$62,"N",Tasks!$I$2:$I$62,">0") | I7: =SUMIFS(Tasks!$I$2:$I$62,Tasks!$D$2:$D$62,$A7) | J7: =SUMIFS(Tasks!$M$2:$M$62,Tasks!$D$2:$D$62,$A7) | K7: =SUMIFS(Tasks!$P$2:$P$62,Tasks!$D$2:$D$62,$A7) | L7: =SUMIFS(Tasks!$T$2:$T$62,Tasks!$D$2:$D$62,$A7) | M7: =SUMIFS(Tasks!$U$2:$U$62,Tasks!$D$2:$D$62,$A7) | N7: =IF(SUMIFS(Tasks!$M$2:$M$62,Tasks!$D$2:$D$62,$A7,Tasks!$S$2:$S$62,"Y")=0,"",L7/SUMIFS(Tasks!$M$2:$M$62,Tasks!$D$2:$D$62,$A7,Tasks!$S$2:$S$62,"Y"))
A8: Remy | B8: Sonnet 5.5 | C8: medium | D8: =INDEX(Calibration!$D$5:$D$11,MATCH(B8&" "&C8,Calibration!$A$5:$A$11,0)) | E8: Tools and npm start | F8: =COUNTIFS(Tasks!$D$2:$D$62,$A8,Tasks!$I$2:$I$62,">0") | G8: =COUNTIFS(Tasks!$D$2:$D$62,$A8,Tasks!$S$2:$S$62,"Y") | H8: =COUNTIFS(Tasks!$D$2:$D$62,$A8,Tasks!$S$2:$S$62,"N")-COUNTIFS(Tasks!$D$2:$D$62,$A8,Tasks!$S$2:$S$62,"N",Tasks!$I$2:$I$62,">0") | I8: =SUMIFS(Tasks!$I$2:$I$62,Tasks!$D$2:$D$62,$A8) | J8: =SUMIFS(Tasks!$M$2:$M$62,Tasks!$D$2:$D$62,$A8) | K8: =SUMIFS(Tasks!$P$2:$P$62,Tasks!$D$2:$D$62,$A8) | L8: =SUMIFS(Tasks!$T$2:$T$62,Tasks!$D$2:$D$62,$A8) | M8: =SUMIFS(Tasks!$U$2:$U$62,Tasks!$D$2:$D$62,$A8) | N8: =IF(SUMIFS(Tasks!$M$2:$M$62,Tasks!$D$2:$D$62,$A8,Tasks!$S$2:$S$62,"Y")=0,"",L8/SUMIFS(Tasks!$M$2:$M$62,Tasks!$D$2:$D$62,$A8,Tasks!$S$2:$S$62,"Y"))
A9: Noor | B9: Opus 5.5 | C9: low | D9: =INDEX(Calibration!$D$5:$D$11,MATCH(B9&" "&C9,Calibration!$A$5:$A$11,0)) | E9: Fixture recording | F9: =COUNTIFS(Tasks!$D$2:$D$62,$A9,Tasks!$I$2:$I$62,">0") | G9: =COUNTIFS(Tasks!$D$2:$D$62,$A9,Tasks!$S$2:$S$62,"Y") | H9: =COUNTIFS(Tasks!$D$2:$D$62,$A9,Tasks!$S$2:$S$62,"N")-COUNTIFS(Tasks!$D$2:$D$62,$A9,Tasks!$S$2:$S$62,"N",Tasks!$I$2:$I$62,">0") | I9: =SUMIFS(Tasks!$I$2:$I$62,Tasks!$D$2:$D$62,$A9) | J9: =SUMIFS(Tasks!$M$2:$M$62,Tasks!$D$2:$D$62,$A9) | K9: =SUMIFS(Tasks!$P$2:$P$62,Tasks!$D$2:$D$62,$A9) | L9: =SUMIFS(Tasks!$T$2:$T$62,Tasks!$D$2:$D$62,$A9) | M9: =SUMIFS(Tasks!$U$2:$U$62,Tasks!$D$2:$D$62,$A9) | N9: =IF(SUMIFS(Tasks!$M$2:$M$62,Tasks!$D$2:$D$62,$A9,Tasks!$S$2:$S$62,"Y")=0,"",L9/SUMIFS(Tasks!$M$2:$M$62,Tasks!$D$2:$D$62,$A9,Tasks!$S$2:$S$62,"Y"))
A10: Total | F10: =SUM(F2:F9) | G10: =SUM(G2:G9) | H10: =SUM(H2:H9) | I10: =SUM(I2:I9) | J10: =SUM(J2:J9) | K10: =SUM(K2:K9) | L10: =SUM(L2:L9) | M10: =SUM(M2:M9)
A12: Each agent is one persistent worker with a fixed model and effort; it keeps its lane across waves and is continued, not restarted, for its next task. Every Tasks row (including rejected attempts) names its agent in Owner agent.

Sheet Calibration
A1: Calibration: model and effort multipliers
A2: Adjusted SP = baseline SP × multiplier. Raw actual SP = runtime minutes ÷ 20. Normalised actual SP = raw ÷ multiplier. Ratio > 1 means that model/effort ran slower than estimated; the implied multiplier is what the data so far suggests.
A4: Key | B4: Model | C4: Effort | D4: Multiplier | E4: Reasoning | F4: Accepted tasks | G4: Baseline SP (accepted) | H4: Adjusted SP (accepted) | I4: Raw actual SP | J4: Actual ÷ estimate (raw ÷ adjusted) | K4: Implied multiplier (raw ÷ baseline)
A5: =B5&" "&C5 | B5: Opus 5.5 | C5: medium | D5: 1 | E5: Baseline by definition: 1 SP = up to 20 min of Opus 5.5 at medium effort. | F5: =COUNTIFS(Tasks!$J$2:$J$62,$B5,Tasks!$K$2:$K$62,$C5,Tasks!$S$2:$S$62,"Y") | G5: =SUMIFS(Tasks!$I$2:$I$62,Tasks!$J$2:$J$62,$B5,Tasks!$K$2:$K$62,$C5,Tasks!$S$2:$S$62,"Y") | H5: =SUMIFS(Tasks!$M$2:$M$62,Tasks!$J$2:$J$62,$B5,Tasks!$K$2:$K$62,$C5,Tasks!$S$2:$S$62,"Y") | I5: =SUMIFS(Tasks!$T$2:$T$62,Tasks!$J$2:$J$62,$B5,Tasks!$K$2:$K$62,$C5,Tasks!$S$2:$S$62,"Y") | J5: =IF(H5=0,"",I5/H5) | K5: =IF(G5=0,"",I5/G5)
A6: =B6&" "&C6 | B6: Opus 5.5 | C6: high | D6: 1.2 | E6: Fixed by Soham. More deliberation per step: roughly +20% runtime for the same task. | F6: =COUNTIFS(Tasks!$J$2:$J$62,$B6,Tasks!$K$2:$K$62,$C6,Tasks!$S$2:$S$62,"Y") | G6: =SUMIFS(Tasks!$I$2:$I$62,Tasks!$J$2:$J$62,$B6,Tasks!$K$2:$K$62,$C6,Tasks!$S$2:$S$62,"Y") | H6: =SUMIFS(Tasks!$M$2:$M$62,Tasks!$J$2:$J$62,$B6,Tasks!$K$2:$K$62,$C6,Tasks!$S$2:$S$62,"Y") | I6: =SUMIFS(Tasks!$T$2:$T$62,Tasks!$J$2:$J$62,$B6,Tasks!$K$2:$K$62,$C6,Tasks!$S$2:$S$62,"Y") | J6: =IF(H6=0,"",I6/H6) | K6: =IF(G6=0,"",I6/G6)
A7: =B7&" "&C7 | B7: Opus 5.5 | C7: low | D7: 0.85 | E7: Brief's starting point. Less thinking per step, but tool calls and test runs don't shrink, so the saving (-15%) is smaller than the high premium (+20%). | F7: =COUNTIFS(Tasks!$J$2:$J$62,$B7,Tasks!$K$2:$K$62,$C7,Tasks!$S$2:$S$62,"Y") | G7: =SUMIFS(Tasks!$I$2:$I$62,Tasks!$J$2:$J$62,$B7,Tasks!$K$2:$K$62,$C7,Tasks!$S$2:$S$62,"Y") | H7: =SUMIFS(Tasks!$M$2:$M$62,Tasks!$J$2:$J$62,$B7,Tasks!$K$2:$K$62,$C7,Tasks!$S$2:$S$62,"Y") | I7: =SUMIFS(Tasks!$T$2:$T$62,Tasks!$J$2:$J$62,$B7,Tasks!$K$2:$K$62,$C7,Tasks!$S$2:$S$62,"Y") | J7: =IF(H7=0,"",I7/H7) | K7: =IF(G7=0,"",I7/G7)
A8: =B8&" "&C8 | B8: Opus 5.5 | C8: xhigh | D8: 1.45 | E8: Brief's starting point. Roughly one more high-sized step above high (+25% on top of 1.2), as thinking budgets grow faster at the top end. | F8: =COUNTIFS(Tasks!$J$2:$J$62,$B8,Tasks!$K$2:$K$62,$C8,Tasks!$S$2:$S$62,"Y") | G8: =SUMIFS(Tasks!$I$2:$I$62,Tasks!$J$2:$J$62,$B8,Tasks!$K$2:$K$62,$C8,Tasks!$S$2:$S$62,"Y") | H8: =SUMIFS(Tasks!$M$2:$M$62,Tasks!$J$2:$J$62,$B8,Tasks!$K$2:$K$62,$C8,Tasks!$S$2:$S$62,"Y") | I8: =SUMIFS(Tasks!$T$2:$T$62,Tasks!$J$2:$J$62,$B8,Tasks!$K$2:$K$62,$C8,Tasks!$S$2:$S$62,"Y") | J8: =IF(H8=0,"",I8/H8) | K8: =IF(G8=0,"",I8/G8)
A9: =B9&" "&C9 | B9: Opus 5.5 | C9: max | D9: 1.75 | E9: Extrapolated: another step of about +0.3 above xhigh. Not used in this plan. | F9: =COUNTIFS(Tasks!$J$2:$J$62,$B9,Tasks!$K$2:$K$62,$C9,Tasks!$S$2:$S$62,"Y") | G9: =SUMIFS(Tasks!$I$2:$I$62,Tasks!$J$2:$J$62,$B9,Tasks!$K$2:$K$62,$C9,Tasks!$S$2:$S$62,"Y") | H9: =SUMIFS(Tasks!$M$2:$M$62,Tasks!$J$2:$J$62,$B9,Tasks!$K$2:$K$62,$C9,Tasks!$S$2:$S$62,"Y") | I9: =SUMIFS(Tasks!$T$2:$T$62,Tasks!$J$2:$J$62,$B9,Tasks!$K$2:$K$62,$C9,Tasks!$S$2:$S$62,"Y") | J9: =IF(H9=0,"",I9/H9) | K9: =IF(G9=0,"",I9/G9)
A10: =B10&" "&C10 | B10: Sonnet 5.5 | C10: medium | D10: 0.7 | E10: Brief's starting point for a smaller model at medium. Faster output, partly offset by more retries on edge cases. Used only for simple, well-specified tasks. | F10: =COUNTIFS(Tasks!$J$2:$J$62,$B10,Tasks!$K$2:$K$62,$C10,Tasks!$S$2:$S$62,"Y") | G10: =SUMIFS(Tasks!$I$2:$I$62,Tasks!$J$2:$J$62,$B10,Tasks!$K$2:$K$62,$C10,Tasks!$S$2:$S$62,"Y") | H10: =SUMIFS(Tasks!$M$2:$M$62,Tasks!$J$2:$J$62,$B10,Tasks!$K$2:$K$62,$C10,Tasks!$S$2:$S$62,"Y") | I10: =SUMIFS(Tasks!$T$2:$T$62,Tasks!$J$2:$J$62,$B10,Tasks!$K$2:$K$62,$C10,Tasks!$S$2:$S$62,"Y") | J10: =IF(H10=0,"",I10/H10) | K10: =IF(G10=0,"",I10/G10)
A11: =B11&" "&C11 | B11: Haiku 5.5 | C11: medium | D11: 0.55 | E11: Extrapolated below Sonnet. Not used in this plan. | F11: =COUNTIFS(Tasks!$J$2:$J$62,$B11,Tasks!$K$2:$K$62,$C11,Tasks!$S$2:$S$62,"Y") | G11: =SUMIFS(Tasks!$I$2:$I$62,Tasks!$J$2:$J$62,$B11,Tasks!$K$2:$K$62,$C11,Tasks!$S$2:$S$62,"Y") | H11: =SUMIFS(Tasks!$M$2:$M$62,Tasks!$J$2:$J$62,$B11,Tasks!$K$2:$K$62,$C11,Tasks!$S$2:$S$62,"Y") | I11: =SUMIFS(Tasks!$T$2:$T$62,Tasks!$J$2:$J$62,$B11,Tasks!$K$2:$K$62,$C11,Tasks!$S$2:$S$62,"Y") | J11: =IF(H11=0,"",I11/H11) | K11: =IF(G11=0,"",I11/G11)

Sheet Summary
A1: Summary: estimated vs actual SP
A2: How to use: fill in only the yellow cells on Tasks (Start, End, Attempts, PR link, Accepted, Notes) and on Stories (Status, Accepted). Log a rejected attempt on its own Tasks row: same ID, Story ID, Wave, Owner agent, Model and Effort, blank Baseline SP, Accepted = N, and the reason in Notes. Blue = typed-in value, black = formula, green = link to another tab.
A4: By story
A5: Story | B5: Story estimate SP (Phase 1) | C5: Task baseline SP (Phase 2) | D5: Task adjusted SP | E5: Raw actual SP | F5: Normalised actual SP | G5: Variance vs task baseline | H5: Accepted
A6: =Stories!A2 | B6: =Stories!E2 | C6: =SUMIFS(Tasks!$I$2:$I$62,Tasks!$B$2:$B$62,A6) | D6: =SUMIFS(Tasks!$M$2:$M$62,Tasks!$B$2:$B$62,A6) | E6: =SUMIFS(Tasks!$T$2:$T$62,Tasks!$B$2:$B$62,A6) | F6: =SUMIFS(Tasks!$U$2:$U$62,Tasks!$B$2:$B$62,A6) | G6: =IF(F6=0,"",F6-C6) | H6: =Stories!K2
A7: =Stories!A3 | B7: =Stories!E3 | C7: =SUMIFS(Tasks!$I$2:$I$62,Tasks!$B$2:$B$62,A7) | D7: =SUMIFS(Tasks!$M$2:$M$62,Tasks!$B$2:$B$62,A7) | E7: =SUMIFS(Tasks!$T$2:$T$62,Tasks!$B$2:$B$62,A7) | F7: =SUMIFS(Tasks!$U$2:$U$62,Tasks!$B$2:$B$62,A7) | G7: =IF(F7=0,"",F7-C7) | H7: =Stories!K3
A8: =Stories!A4 | B8: =Stories!E4 | C8: =SUMIFS(Tasks!$I$2:$I$62,Tasks!$B$2:$B$62,A8) | D8: =SUMIFS(Tasks!$M$2:$M$62,Tasks!$B$2:$B$62,A8) | E8: =SUMIFS(Tasks!$T$2:$T$62,Tasks!$B$2:$B$62,A8) | F8: =SUMIFS(Tasks!$U$2:$U$62,Tasks!$B$2:$B$62,A8) | G8: =IF(F8=0,"",F8-C8) | H8: =Stories!K4
A9: =Stories!A5 | B9: =Stories!E5 | C9: =SUMIFS(Tasks!$I$2:$I$62,Tasks!$B$2:$B$62,A9) | D9: =SUMIFS(Tasks!$M$2:$M$62,Tasks!$B$2:$B$62,A9) | E9: =SUMIFS(Tasks!$T$2:$T$62,Tasks!$B$2:$B$62,A9) | F9: =SUMIFS(Tasks!$U$2:$U$62,Tasks!$B$2:$B$62,A9) | G9: =IF(F9=0,"",F9-C9) | H9: =Stories!K5
A10: =Stories!A6 | B10: =Stories!E6 | C10: =SUMIFS(Tasks!$I$2:$I$62,Tasks!$B$2:$B$62,A10) | D10: =SUMIFS(Tasks!$M$2:$M$62,Tasks!$B$2:$B$62,A10) | E10: =SUMIFS(Tasks!$T$2:$T$62,Tasks!$B$2:$B$62,A10) | F10: =SUMIFS(Tasks!$U$2:$U$62,Tasks!$B$2:$B$62,A10) | G10: =IF(F10=0,"",F10-C10) | H10: =Stories!K6
A11: =Stories!A7 | B11: =Stories!E7 | C11: =SUMIFS(Tasks!$I$2:$I$62,Tasks!$B$2:$B$62,A11) | D11: =SUMIFS(Tasks!$M$2:$M$62,Tasks!$B$2:$B$62,A11) | E11: =SUMIFS(Tasks!$T$2:$T$62,Tasks!$B$2:$B$62,A11) | F11: =SUMIFS(Tasks!$U$2:$U$62,Tasks!$B$2:$B$62,A11) | G11: =IF(F11=0,"",F11-C11) | H11: =Stories!K7
A12: =Stories!A8 | B12: =Stories!E8 | C12: =SUMIFS(Tasks!$I$2:$I$62,Tasks!$B$2:$B$62,A12) | D12: =SUMIFS(Tasks!$M$2:$M$62,Tasks!$B$2:$B$62,A12) | E12: =SUMIFS(Tasks!$T$2:$T$62,Tasks!$B$2:$B$62,A12) | F12: =SUMIFS(Tasks!$U$2:$U$62,Tasks!$B$2:$B$62,A12) | G12: =IF(F12=0,"",F12-C12) | H12: =Stories!K8
A13: =Stories!A9 | B13: =Stories!E9 | C13: =SUMIFS(Tasks!$I$2:$I$62,Tasks!$B$2:$B$62,A13) | D13: =SUMIFS(Tasks!$M$2:$M$62,Tasks!$B$2:$B$62,A13) | E13: =SUMIFS(Tasks!$T$2:$T$62,Tasks!$B$2:$B$62,A13) | F13: =SUMIFS(Tasks!$U$2:$U$62,Tasks!$B$2:$B$62,A13) | G13: =IF(F13=0,"",F13-C13) | H13: =Stories!K9
A14: =Stories!A10 | B14: =Stories!E10 | C14: =SUMIFS(Tasks!$I$2:$I$62,Tasks!$B$2:$B$62,A14) | D14: =SUMIFS(Tasks!$M$2:$M$62,Tasks!$B$2:$B$62,A14) | E14: =SUMIFS(Tasks!$T$2:$T$62,Tasks!$B$2:$B$62,A14) | F14: =SUMIFS(Tasks!$U$2:$U$62,Tasks!$B$2:$B$62,A14) | G14: =IF(F14=0,"",F14-C14) | H14: =Stories!K10
A15: =Stories!A11 | B15: =Stories!E11 | C15: =SUMIFS(Tasks!$I$2:$I$62,Tasks!$B$2:$B$62,A15) | D15: =SUMIFS(Tasks!$M$2:$M$62,Tasks!$B$2:$B$62,A15) | E15: =SUMIFS(Tasks!$T$2:$T$62,Tasks!$B$2:$B$62,A15) | F15: =SUMIFS(Tasks!$U$2:$U$62,Tasks!$B$2:$B$62,A15) | G15: =IF(F15=0,"",F15-C15) | H15: =Stories!K11
A16: =Stories!A12 | B16: =Stories!E12 | C16: =SUMIFS(Tasks!$I$2:$I$62,Tasks!$B$2:$B$62,A16) | D16: =SUMIFS(Tasks!$M$2:$M$62,Tasks!$B$2:$B$62,A16) | E16: =SUMIFS(Tasks!$T$2:$T$62,Tasks!$B$2:$B$62,A16) | F16: =SUMIFS(Tasks!$U$2:$U$62,Tasks!$B$2:$B$62,A16) | G16: =IF(F16=0,"",F16-C16) | H16: =Stories!K12
A17: =Stories!A13 | B17: =Stories!E13 | C17: =SUMIFS(Tasks!$I$2:$I$62,Tasks!$B$2:$B$62,A17) | D17: =SUMIFS(Tasks!$M$2:$M$62,Tasks!$B$2:$B$62,A17) | E17: =SUMIFS(Tasks!$T$2:$T$62,Tasks!$B$2:$B$62,A17) | F17: =SUMIFS(Tasks!$U$2:$U$62,Tasks!$B$2:$B$62,A17) | G17: =IF(F17=0,"",F17-C17) | H17: =Stories!K13
A18: Total | B18: =SUM(B6:B17) | C18: =SUM(C6:C17) | D18: =SUM(D6:D17) | E18: =SUM(E6:E17) | F18: =SUM(F6:F17) | G18: =IF(F18=0,"",F18-SUMIFS(C6:C17,H6:H17,"Y"))
A20: By wave
A21: Wave | B21: Tasks | C21: Baseline SP | D21: Adjusted SP | E21: Raw actual SP | F21: Normalised actual SP | G21: Variance vs baseline | H21: Tasks accepted
A22: 1 | B22: =COUNTIFS(Tasks!$E$2:$E$62,A22,Tasks!$I$2:$I$62,">0") | C22: =SUMIFS(Tasks!$I$2:$I$62,Tasks!$E$2:$E$62,A22) | D22: =SUMIFS(Tasks!$M$2:$M$62,Tasks!$E$2:$E$62,A22) | E22: =SUMIFS(Tasks!$T$2:$T$62,Tasks!$E$2:$E$62,A22) | F22: =SUMIFS(Tasks!$U$2:$U$62,Tasks!$E$2:$E$62,A22) | G22: =IF(F22=0,"",F22-SUMIFS(Tasks!$I$2:$I$62,Tasks!$E$2:$E$62,A22,Tasks!$S$2:$S$62,"Y")) | H22: =COUNTIFS(Tasks!$E$2:$E$62,A22,Tasks!$S$2:$S$62,"Y")
A23: 2 | B23: =COUNTIFS(Tasks!$E$2:$E$62,A23,Tasks!$I$2:$I$62,">0") | C23: =SUMIFS(Tasks!$I$2:$I$62,Tasks!$E$2:$E$62,A23) | D23: =SUMIFS(Tasks!$M$2:$M$62,Tasks!$E$2:$E$62,A23) | E23: =SUMIFS(Tasks!$T$2:$T$62,Tasks!$E$2:$E$62,A23) | F23: =SUMIFS(Tasks!$U$2:$U$62,Tasks!$E$2:$E$62,A23) | G23: =IF(F23=0,"",F23-SUMIFS(Tasks!$I$2:$I$62,Tasks!$E$2:$E$62,A23,Tasks!$S$2:$S$62,"Y")) | H23: =COUNTIFS(Tasks!$E$2:$E$62,A23,Tasks!$S$2:$S$62,"Y")
A24: 3 | B24: =COUNTIFS(Tasks!$E$2:$E$62,A24,Tasks!$I$2:$I$62,">0") | C24: =SUMIFS(Tasks!$I$2:$I$62,Tasks!$E$2:$E$62,A24) | D24: =SUMIFS(Tasks!$M$2:$M$62,Tasks!$E$2:$E$62,A24) | E24: =SUMIFS(Tasks!$T$2:$T$62,Tasks!$E$2:$E$62,A24) | F24: =SUMIFS(Tasks!$U$2:$U$62,Tasks!$E$2:$E$62,A24) | G24: =IF(F24=0,"",F24-SUMIFS(Tasks!$I$2:$I$62,Tasks!$E$2:$E$62,A24,Tasks!$S$2:$S$62,"Y")) | H24: =COUNTIFS(Tasks!$E$2:$E$62,A24,Tasks!$S$2:$S$62,"Y")
A25: 4 | B25: =COUNTIFS(Tasks!$E$2:$E$62,A25,Tasks!$I$2:$I$62,">0") | C25: =SUMIFS(Tasks!$I$2:$I$62,Tasks!$E$2:$E$62,A25) | D25: =SUMIFS(Tasks!$M$2:$M$62,Tasks!$E$2:$E$62,A25) | E25: =SUMIFS(Tasks!$T$2:$T$62,Tasks!$E$2:$E$62,A25) | F25: =SUMIFS(Tasks!$U$2:$U$62,Tasks!$E$2:$E$62,A25) | G25: =IF(F25=0,"",F25-SUMIFS(Tasks!$I$2:$I$62,Tasks!$E$2:$E$62,A25,Tasks!$S$2:$S$62,"Y")) | H25: =COUNTIFS(Tasks!$E$2:$E$62,A25,Tasks!$S$2:$S$62,"Y")
A26: 5 | B26: =COUNTIFS(Tasks!$E$2:$E$62,A26,Tasks!$I$2:$I$62,">0") | C26: =SUMIFS(Tasks!$I$2:$I$62,Tasks!$E$2:$E$62,A26) | D26: =SUMIFS(Tasks!$M$2:$M$62,Tasks!$E$2:$E$62,A26) | E26: =SUMIFS(Tasks!$T$2:$T$62,Tasks!$E$2:$E$62,A26) | F26: =SUMIFS(Tasks!$U$2:$U$62,Tasks!$E$2:$E$62,A26) | G26: =IF(F26=0,"",F26-SUMIFS(Tasks!$I$2:$I$62,Tasks!$E$2:$E$62,A26,Tasks!$S$2:$S$62,"Y")) | H26: =COUNTIFS(Tasks!$E$2:$E$62,A26,Tasks!$S$2:$S$62,"Y")
A27: Total | B27: =SUM(B22:B26) | C27: =SUM(C22:C26) | D27: =SUM(D22:D26) | E27: =SUM(E22:E26) | F27: =SUM(F22:F26) | H27: =SUM(H22:H26)
A29: Planning phases (actuals only; not estimated, not in the totals above)
A30: Phase | B30: Agent | C30: Model / effort | D30: Runtime (min) | E30: Raw actual SP | F30: Accepted | G30: Source
A31: Phase 1 | B31: Product agent | C31: Opus 5.5 high | D31: 3.86 | E31: =D31/20 | F31: Y | G31: Sub-agent duration reported by Claude Code, 2026-10-19
A32: Phase 2 | B32: Dev lead agent | C32: Opus 5.5 high | D32: 11.56 | E32: =D32/20 | F32: Y | G32: Sub-agent duration reported by Claude Code, 2026-10-19
A34: Later list (out of POC scope)
A35: Per-value taint, so external sends of unrelated values after a Legal read are allowed.
A36: Per-record memory labels, instead of scoped audiences.
A37: An LLM-driven agent instead of the scripted one.
A38: A release workflow or UI for the review hold, beyond moving the file in Drive.
A39: Real ID detectors (SSN, passport and so on) beyond the SPECIMEN format.
A40: Google Docs, PDF and OCR input.
A41: Per-team audiences (an Accounting list separate from `internal`).
A42: Copies and summaries carrying the source clearance, and sanitizers or redaction.
A43: Real email.
A44: Drive webhooks.
...
